2022-09-01 22:07:56,984 INFO    StreamThr :23584 [internal.py:wandb_internal():90] W&B internal server running at pid: 23584, started at: 2022-09-01 22:07:56.983588
2022-09-01 22:07:56,993 DEBUG   HandlerThread:23584 [handler.py:handle_request():141] handle_request: status
2022-09-01 22:07:56,998 DEBUG   SenderThread:23584 [sender.py:send_request():316] send_request: status
2022-09-01 22:07:57,002 INFO    WriterThread:23584 [datastore.py:open_for_write():75] open: E:\Code\Kaggle\wandb\run-20220901_220756-3c0leqg5\run-3c0leqg5.wandb
2022-09-01 22:07:57,003 DEBUG   SenderThread:23584 [sender.py:send():302] send: header
2022-09-01 22:07:57,063 DEBUG   SenderThread:23584 [sender.py:send():302] send: run
2022-09-01 22:08:05,236 ERROR   SenderThread:23584 [internal_api.py:execute():207] 401 response executing GraphQL.
2022-09-01 22:08:05,237 ERROR   SenderThread:23584 [internal_api.py:execute():208] {"errors":[{"message":"user is not logged in","path":["upsertBucket"],"extensions":{"code":"PERMISSION_ERROR"}}],"data":{"upsertBucket":null}}
2022-09-01 22:08:06,179 INFO    WriterThread:23584 [datastore.py:close():279] close: E:\Code\Kaggle\wandb\run-20220901_220756-3c0leqg5\run-3c0leqg5.wandb
2022-09-01 22:08:06,179 INFO    HandlerThread:23584 [handler.py:finish():810] shutting down handler
2022-09-01 22:08:06,180 ERROR   StreamThr :23584 [internal.py:wandb_internal():165] Thread SenderThread:
Traceback (most recent call last):
  File "D:\Anaconda3\envs\bigchuang\lib\site-packages\wandb\sdk\lib\retry.py", line 113, in __call__
    result = self._call_fn(*args, **kwargs)
  File "D:\Anaconda3\envs\bigchuang\lib\site-packages\wandb\sdk\internal\internal_api.py", line 204, in execute
    return self.client.execute(*args, **kwargs)  # type: ignore
  File "D:\Anaconda3\envs\bigchuang\lib\site-packages\wandb\vendor\gql-0.2.0\wandb_gql\client.py", line 52, in execute
    result = self._get_result(document, *args, **kwargs)
  File "D:\Anaconda3\envs\bigchuang\lib\site-packages\wandb\vendor\gql-0.2.0\wandb_gql\client.py", line 60, in _get_result
    return self.transport.execute(document, *args, **kwargs)
  File "D:\Anaconda3\envs\bigchuang\lib\site-packages\wandb\vendor\gql-0.2.0\wandb_gql\transport\requests.py", line 39, in execute
    request.raise_for_status()
  File "D:\Anaconda3\envs\bigchuang\lib\site-packages\requests\models.py", line 1021, in raise_for_status
    raise HTTPError(http_error_msg, response=self)
requests.exceptions.HTTPError: 401 Client Error: Unauthorized for url: https://api.wandb.ai/graphql

During handling of the above exception, another exception occurred:

Traceback (most recent call last):
  File "D:\Anaconda3\envs\bigchuang\lib\site-packages\wandb\apis\normalize.py", line 25, in wrapper
    return func(*args, **kwargs)
  File "D:\Anaconda3\envs\bigchuang\lib\site-packages\wandb\sdk\internal\internal_api.py", line 1465, in upsert_run
    response = self.gql(
  File "D:\Anaconda3\envs\bigchuang\lib\site-packages\wandb\sdk\lib\retry.py", line 129, in __call__
    retry_timedelta_triggered = check_retry_fn(e)
  File "D:\Anaconda3\envs\bigchuang\lib\site-packages\wandb\util.py", line 942, in check_retry_fn
    return fallback_retry_fn(e)
  File "D:\Anaconda3\envs\bigchuang\lib\site-packages\wandb\util.py", line 885, in no_retry_auth
    raise CommError("Invalid or missing api_key. Run `wandb login`")
wandb.errors.CommError: Invalid or missing api_key. Run `wandb login`

During handling of the above exception, another exception occurred:

Traceback (most recent call last):
  File "D:\Anaconda3\envs\bigchuang\lib\site-packages\wandb\sdk\internal\internal_util.py", line 51, in run
    self._run()
  File "D:\Anaconda3\envs\bigchuang\lib\site-packages\wandb\sdk\internal\internal_util.py", line 102, in _run
    self._process(record)
  File "D:\Anaconda3\envs\bigchuang\lib\site-packages\wandb\sdk\internal\internal.py", line 310, in _process
    self._sm.send(record)
  File "D:\Anaconda3\envs\bigchuang\lib\site-packages\wandb\sdk\internal\sender.py", line 304, in send
    send_handler(record)
  File "D:\Anaconda3\envs\bigchuang\lib\site-packages\wandb\sdk\internal\sender.py", line 782, in send_run
    self._init_run(run, config_value_dict)
  File "D:\Anaconda3\envs\bigchuang\lib\site-packages\wandb\sdk\internal\sender.py", line 808, in _init_run
    server_run, inserted, server_messages = self._api.upsert_run(
  File "D:\Anaconda3\envs\bigchuang\lib\site-packages\wandb\apis\normalize.py", line 61, in wrapper
    raise CommError(message, err).with_traceback(sys.exc_info()[2])
  File "D:\Anaconda3\envs\bigchuang\lib\site-packages\wandb\apis\normalize.py", line 25, in wrapper
    return func(*args, **kwargs)
  File "D:\Anaconda3\envs\bigchuang\lib\site-packages\wandb\sdk\internal\internal_api.py", line 1465, in upsert_run
    response = self.gql(
  File "D:\Anaconda3\envs\bigchuang\lib\site-packages\wandb\sdk\lib\retry.py", line 129, in __call__
    retry_timedelta_triggered = check_retry_fn(e)
  File "D:\Anaconda3\envs\bigchuang\lib\site-packages\wandb\util.py", line 942, in check_retry_fn
    return fallback_retry_fn(e)
  File "D:\Anaconda3\envs\bigchuang\lib\site-packages\wandb\util.py", line 885, in no_retry_auth
    raise CommError("Invalid or missing api_key. Run `wandb login`")
wandb.errors.CommError: Invalid or missing api_key. Run `wandb login`
